
예외를 처리하는 방법에는 try-catch문을 사용하는 것 외에, 예외 메서드를 선언하는 방법이 있다.

메서드에 예외를 선언하려면, 메서드의 선언부에 throws를 사용해서 메서드 내에서 발생할 수 있는 예외를 적어주기만 하면 되며 예외가 여러 개일 경우에는 쉼표(,)로 구분한다.

만약 모든 예외의 최고 조상인 Exception클래스를 메서드에 선언하면, 이 메서드는 모든 종류의 예외가 발생할 가능성

이 있다는 뜻이다.

이렇게 예외를 선언하면, 이 예외 뿐만 아니라 그 자손 타입의 예외까지도 발생할 수 있다는 점을 생각해야 하며 오버

라이딩 할 때는 단순히 선언된 예외의 개수가 아니라 상속 관계까지 고려해야 한다.

메서드의 선언부에 예외를 선언함으로써 메서드를 사용하려는 사람이 메서드의 선언부를 보았을 때, 이 메서드를 사용

하기 위해서는 어떠한 예외들이 처리되어져야 하는지 쉽게 알 수 있다.

```java
public class Exception4 {
    public static void main(String[] args) throws Exception{
        method1();
    }

    static void method1() throws Exception{
        method2();
    }

    static void method2() throws Exception{
        throw new Exception();
    }
}
```

```java
Exception in thread "main" java.lang.Exception
	at Exception4.method2(Exception4.java:11)
	at Exception4.method1(Exception4.java:7)
	at Exception4.main(Exception4.java:3)
```

위의 실행결과를 보면, 프로그램의 실행도중 java.lang.Exception이 발생하여 비정상적으로 종료 했다는

것과 예외가 발생했을 때 호출스택(call stack)의 내용을 알 수 있다.

- 예외가 발생했을 때, 모두 3개의 메서드(main, method1, method2)가 호출스택에 있었으며,
- 예외가 발생한 곳은 제일 윗줄에 있는 method2()라는 것과
- main메서드가 method1()을, 그리고 method1()은 method2()를 호출했다는 것을 알 수 있다.

위의 코드에서는 method2()에서 ‘throw new Exception()’; 문장에 의해 예외가 강제적으로 발생했으나

try - catch문으로 예외처리를 해주지 않았으므로, method2()는 종료되면서 예외를 자신을 호출한

method1()에게 넘겨준다.

method1()에서도 역시 예외처리를 해주지 않았으므로 종료되면서 main메서드에게 예외를 넘겨준다.

그러나 main메서드에서 조차 예외처리를 해주지 않았으므로 main메서드가 종료되어 프로그램이

예외로 인해 비정상적으로 종료되는 것이다.

이처럼 예외가 발생한 메서드에서 예외처리를 하지 않고 자신을 호출한 메서드에게 예외를 넘겨줄 수는

있지만, 이것으로 예외가 처리된 것은 아니고 예외를 단순히 전달만 하는 것이다.

결국 어느 한 곳에서는 반드시 try - catch문으로 예외처리를 해주어야 한다.

```java
public class Exception4 {
    public static void main(String[] args) throws Exception{
        method1();
    }

    static void method1() {
        try{
            throw new Exception();
        } catch (Exception exception){
            System.out.println("method1 메서드에서 예외가 처리되었습니다.");
            exception.printStackTrace();
        }
    }

    static void method2() throws Exception{
        throw new Exception();
    }
}
```

```java
method1 메서드에서 예외가 처리되었습니다.
java.lang.Exception
	at Exception4.method1(Exception4.java:8)
	at Exception4.main(Exception4.java:3)
```


```java
public class Exception5 {
    public static void main(String[] args) {
        try {
            method1();
        } catch (Exception exception){
            System.out.println("main메서드에서 예외가 처리되었습니다.");
            exception.printStackTrace();
        }
    }

    static void method1() throws Exception{
        throw new Exception();
    }
}
```

```java
main메서드에서 예외가 처리되었습니다.
java.lang.Exception
	at Exception5.method1(Exception5.java:12)
	at Exception5.main(Exception5.java:4)
```

두 예제 모두 main메서드가 method1( )을 호출 하며, method1( )에서 예외가 발생한다.

차이점은 예외처리 방법에 있다.

Exeception4는 method1( )에서 예외처리를 했고, Exception5는 method1( )에서 예외를 선언하여

자신을 호출하는 main메서드에서 예외를 전달했으며, 호출한 main 메서드에서는 try - catch 문으로

예외처리를 했다.

Exception4 처럼 예외가 발생한 메서드(method1) 내에서 처리되어지면, 호출한 main메서드 에서는

예외가 발생했다는 사실조차 모르게 된다.

Exeception5는 처럼 예외가 발생한 메서드에서 예외를 처리하지 않고 호출한 메서드로 넘겨주면,

호출한 메서드에서는 method1( )을 호출한 라인에서 예외가 발생한 것으로 간주되어 이에 대한 처리를 하게 된다.

이처럼 예외가 발생한 메서드 ‘method1( )’ 에서 예외를 처리할 수도 있고, 예외가 발생한 메서드를 호출한

‘main메서드’에서 처리할 수도 있다. 또는 두 메서드가 예외처리를 분담할 수도 있다.

























