# 프로그램 오류

프로그램이 실행 중 어떤 원인에 의해서 오작동을 하거나 비정상적으로 종료되는 경우가 있다.

이러한 결과를 초래하는 원인을 프로그램 에러 또는 오류라고 한다.

이를 발생 시점에 따라 ‘컴파일 에러(compile-time error)’와 ‘런타임 에러(runtime error)‘로 나눌 수

있는데, ‘컴파일 에러’는 컴파일 할 때 발생하는 에러이고 프로그램의 실행 도중에 발생하는 에러를

‘런타임 에러’ 라고 한다. 이 외에도 ‘논리적 에러(logical error)’가 있는데, 컴파일도 잘되고 실행도

잘되지만 의도한 것과 다르게 동작하는 것을 말한다.

컴파일 에러 : 컴파일 시 발생하는 에러

런타임 에러 : 실행 시에 발생하는 에러

논리적 에러 : 실행은 되지만, 의도와 다르게 동작하는 것

컴파일을 에러 없이 성공적으로 마쳤다고 해서 프로그램의 실행 시에도 에러가 발생하지 않는 것은

아니다.

컴파일러가 소스 코드의 기본적인 사항은 컴파일 시에 모두 걸러 줄 수는 있지만, 실행 도중에 발생

할 수 있는 잠재적인 오류까지 검사할 수 없기 때문에 컴파일은 잘되었어도 실행 중에 에러에 의해서

잘된 결과를 얻거나 프로그램이 비정상적으로 종료될 수 있다.

자바에서 실행 시(runtime) 발생할 수 있는 프로그램 오류를 ‘에러(error)’와 ‘예외(exception)’ 두 가지

로 구분하였다.

에러는 메모리 부족(OutOfMemoryError)이나 스택오버플로우(StackOverflowError)와 같이 발생하면

복구할 수 없는 심각한 오류이고, 예외는 발생하더라도 수습될 수 있는 비교적 덜 심각한 것이다.

에러가 발생하면, 프로그램의 비정상적인 종료를 막을 길이 없지만, 예외는 발생하더라도

프로그래머가 이에 대한 적절한 코드를 미리 작성해 놓음으로써 프로그램의 비정상적인 종료를

막을 수 있다.

# 예외 클래스의 계층구조

자바에서는 실행 시 발생할 수 있는 오류(Exception과 Error)를 클래스로 정의 하였다.

앞서 배운 것처럼 모든 클래스의 조상은 Object클래스이므로 Exception과 Error클래스 역시

Object클래스의 자손들이다.

![Untitled](https://prod-files-secure.s3.us-west-2.amazonaws.com/ea204791-94b0-4594-95e9-37705edf8245/e39ae688-bb08-4347-b583-32f86b348a51/Untitled.png)

# 예외처리하기

프로그램의 실행 도중에 발생하는 에러는 어쩔 수 없지만, 예외는 프로그래머가 이에 대한 처리를

미리 해주어야 한다.

예외처리(exception)란, 프로그램 실행 시 발생할 수 있는 예기치 못한 예외의 발생에 대비한 코드를

작성하는 것이며, 예외 처리의 목적은 예외의 발생으로 인한 실행 중인 프로그램의 갑작스러운

비정상 종료를 막고, 정상적인 실행 상태를 유지할 수도 있도록 하는 것이다.

발생한 예외를 처리하지 못하면, 프로그램은 비정상적으로 종료 되며, 처리되지 못한

예외(uncaught exception)는 JVM의 ‘예외처리기(UncaughtExceptionHandler)’가 받아서 예외의 원인

을 화면에 출력한다.

예외를 처리하기 위해서는 try - catch문을 사용해야 한다.

```java
package ch07;

public class ExceptionEx1 {

	public static void main(String[] args) {
		try {
			try {} catch (Exception e) {}	
		} catch (Exception e) {
			try {} catch (Exception e) {} // 에러 변수 e가 중복 선언되었다.
		} //try-catch의 끝
		
		try {
			
		} catch (Exception e) {
			
		} // try-catch의 끝
	} // main메서드의 끝

}

```


try - catch문의 사용 예를 보여주기 위해서 작성한 코드이다.

하나의 메서드 내에 여려 개의 try-catch문이 사용될 수 있으며, try블럭 또는 catch블럭에 또 다른

try - catch문이 포함될 수 있다. 왜냐하면 catch블럭 내의 코드에서도 예외가 발생할 수 있기 때문

이다.

catch블럭 내에 또 하나의 try - catch문이 포함된 경우, 같은 이름의 참조 변수를 사용해서는 안된다.

각 catch블럭에 선언된 두 참조 변수의 영역이 서로 겹치므로 다른 이름을 사용해야만 서로 구별되기

때문이다.

```java

public class ExceptionEx2 {

	public static void main(String[] args) {
		int number = 100;
		int result = 0;
		
		for(int i = 0; i < 10; i++) {
			result = number / (int)(Math.random() * 10);
			System.out.println(result);
		}
	}
}

```

```java
11
14
20
50
12
100
12
Exception in thread "main" java.lang.ArithmeticException: / by zero
	at ExceptionEx2.main(ExceptionEx2.java:8)
```


결과에 나타난 메시지를 보면 예외의 발생 원인과 위치를 알 수 있다.

이 메시지를 보면 0으로 나누려 했기 때문에 ‘ArithmeticException’이 발생했고, 발생 위치는

ExceptionEx2 클래스의 main메서드라는 것을 알 수 있다.

ArithmeticException은 산술 연산 과정에서 오류가 있을 때 발생하는 예외이며, 정수는 0으로 나누는

것이 금지 되어있기 때문에 발생했다. 하지만 실수를 0으로 나누는 것은 금지되어 있지 않으며 예외가 발생하지 않는다.

여기서 예외 처리 구문을 추가해서 실행 도중 예외가 발생하더라도 프로그램이 실행 도중에 비정상

적으로 종료되지 않도록 수정한다면 아래와 같은 코드가 된다.

```java
package ch07;

public class ExceptionEx2 {

	public static void main(String[] args) {
		int number = 100;
		int result = 0;
		
		for(int i = 0; i < 10; i++) {
			try {
				result = number / (int)(Math.random() * 10);
				System.out.println(result);
			} catch (ArithmeticException e) {
				System.out.println("0");
			}
		}
	}
}

```

```java
16
100
25
0
50
25
11
16
14
0
```


try - catch문을 추가해서 ArithmeticException이 발생했을 경우에는 0을 화면에 출력하도록 하였다.

만약 예외 처리를 하지 않았다면 4번째의 반복문 결과가 나오기 전에 예외가 발생하여 프로그램이

비정상적으로 끝나게 된다.












